<?xml version="1.0"?>
<robot name="leap_hand">
  <link name="palm">
    <visual>
      <origin xyz="0 0 0" rpy="0 0 0"/>
      <geometry><box size="0.1 0.1 0.02"/></geometry>
      <material name="blue">
        <color rgba="0 0 0.8 1"/>
      </material>
    </visual>
  </link>

  <joint name="if_mcp" type="revolute">
    <parent link="palm"/>
    <child link="if_link_0"/>
    <origin xyz="-0.01 0.04 0.05" rpy="0 0 0"/>
    <axis xyz="0 1 0"/>
    <limit lower="-3.14" upper="3.14" effort="10" velocity="10"/>
  </joint>

  <link name="if_link_0">
    <visual>
      <origin xyz="0 0 0.02" rpy="0 0 0"/>
      <geometry><cylinder radius="0.008" length="0.04"/></geometry>
      <material name="white">
        <color rgba="1 1 1 1"/>
      </material>
    </visual>
  </link>

  <joint name="if_rot" type="revolute">
    <parent link="if_link_0"/>
    <child link="if_link_1"/>
    <origin xyz="0 0 0.04" rpy="0 0 0"/>
    <axis xyz="0 1 0"/>
    <limit lower="-3.14" upper="3.14" effort="10" velocity="10"/>
  </joint>

  <link name="if_link_1">
    <visual>
      <origin xyz="0 0 0.02" rpy="0 0 0"/>
      <geometry><cylinder radius="0.008" length="0.04"/></geometry>
      <material name="white">
        <color rgba="1 1 1 1"/>
      </material>
    </visual>
  </link>

  <joint name="if_pip" type="revolute">
    <parent link="if_link_1"/>
    <child link="if_link_2"/>
    <origin xyz="0 0 0.04" rpy="0 0 0"/>
    <axis xyz="0 1 0"/>
    <limit lower="-3.14" upper="3.14" effort="10" velocity="10"/>
  </joint>

  <link name="if_link_2">
    <visual>
      <origin xyz="0 0 0.02" rpy="0 0 0"/>
      <geometry><cylinder radius="0.008" length="0.04"/></geometry>
      <material name="white">
        <color rgba="1 1 1 1"/>
      </material>
    </visual>
  </link>

  <joint name="if_dip" type="revolute">
    <parent link="if_link_2"/>
    <child link="if_link_3"/>
    <origin xyz="0 0 0.04" rpy="0 0 0"/>
    <axis xyz="0 1 0"/>
    <limit lower="-3.14" upper="3.14" effort="10" velocity="10"/>
  </joint>

  <link name="if_link_3">
    <visual>
      <origin xyz="0 0 0.02" rpy="0 0 0"/>
      <geometry><cylinder radius="0.008" length="0.04"/></geometry>
      <material name="white">
        <color rgba="1 1 1 1"/>
      </material>
    </visual>
  </link>

  <joint name="mf_mcp" type="revolute">
    <parent link="palm"/>
    <child link="mf_link_0"/>
    <origin xyz="-0.01 0.0 0.05" rpy="0 0 0"/>
    <axis xyz="0 1 0"/>
    <limit lower="-3.14" upper="3.14" effort="10" velocity="10"/>
  </joint>

  <link name="mf_link_0">
    <visual>
      <origin xyz="0 0 0.02" rpy="0 0 0"/>
      <geometry><cylinder radius="0.008" length="0.04"/></geometry>
      <material name="white">
        <color rgba="1 1 1 1"/>
      </material>
    </visual>
  </link>

  <joint name="mf_rot" type="revolute">
    <parent link="mf_link_0"/>
    <child link="mf_link_1"/>
    <origin xyz="0 0 0.04" rpy="0 0 0"/>
    <axis xyz="0 1 0"/>
    <limit lower="-3.14" upper="3.14" effort="10" velocity="10"/>
  </joint>

  <link name="mf_link_1">
    <visual>
      <origin xyz="0 0 0.02" rpy="0 0 0"/>
      <geometry><cylinder radius="0.008" length="0.04"/></geometry>
      <material name="white">
        <color rgba="1 1 1 1"/>
      </material>
    </visual>
  </link>

  <joint name="mf_pip" type="revolute">
    <parent link="mf_link_1"/>
    <child link="mf_link_2"/>
    <origin xyz="0 0 0.04" rpy="0 0 0"/>
    <axis xyz="0 1 0"/>
    <limit lower="-3.14" upper="3.14" effort="10" velocity="10"/>
  </joint>

  <link name="mf_link_2">
    <visual>
      <origin xyz="0 0 0.02" rpy="0 0 0"/>
      <geometry><cylinder radius="0.008" length="0.04"/></geometry>
      <material name="white">
        <color rgba="1 1 1 1"/>
      </material>
    </visual>
  </link>

  <joint name="mf_dip" type="revolute">
    <parent link="mf_link_2"/>
    <child link="mf_link_3"/>
    <origin xyz="0 0 0.04" rpy="0 0 0"/>
    <axis xyz="0 1 0"/>
    <limit lower="-3.14" upper="3.14" effort="10" velocity="10"/>
  </joint>

  <link name="mf_link_3">
    <visual>
      <origin xyz="0 0 0.02" rpy="0 0 0"/>
      <geometry><cylinder radius="0.008" length="0.04"/></geometry>
      <material name="white">
        <color rgba="1 1 1 1"/>
      </material>
    </visual>
  </link>

  <joint name="rf_mcp" type="revolute">
    <parent link="palm"/>
    <child link="rf_link_0"/>
    <origin xyz="-0.01 -0.04 0.05" rpy="0 0 0"/>
    <axis xyz="0 1 0"/>
    <limit lower="-3.14" upper="3.14" effort="10" velocity="10"/>
  </joint>

  <link name="rf_link_0">
    <visual>
      <origin xyz="0 0 0.02" rpy="0 0 0"/>
      <geometry><cylinder radius="0.008" length="0.04"/></geometry>
      <material name="white">
        <color rgba="1 1 1 1"/>
      </material>
    </visual>
  </link>

  <joint name="rf_rot" type="revolute">
    <parent link="rf_link_0"/>
    <child link="rf_link_1"/>
    <origin xyz="0 0 0.04" rpy="0 0 0"/>
    <axis xyz="0 1 0"/>
    <limit lower="-3.14" upper="3.14" effort="10" velocity="10"/>
  </joint>

  <link name="rf_link_1">
    <visual>
      <origin xyz="0 0 0.02" rpy="0 0 0"/>
      <geometry><cylinder radius="0.008" length="0.04"/></geometry>
      <material name="white">
        <color rgba="1 1 1 1"/>
      </material>
    </visual>
  </link>

  <joint name="rf_pip" type="revolute">
    <parent link="rf_link_1"/>
    <child link="rf_link_2"/>
    <origin xyz="0 0 0.04" rpy="0 0 0"/>
    <axis xyz="0 1 0"/>
    <limit lower="-3.14" upper="3.14" effort="10" velocity="10"/>
  </joint>

  <link name="rf_link_2">
    <visual>
      <origin xyz="0 0 0.02" rpy="0 0 0"/>
      <geometry><cylinder radius="0.008" length="0.04"/></geometry>
      <material name="white">
        <color rgba="1 1 1 1"/>
      </material>
    </visual>
  </link>

  <joint name="rf_dip" type="revolute">
    <parent link="rf_link_2"/>
    <child link="rf_link_3"/>
    <origin xyz="0 0 0.04" rpy="0 0 0"/>
    <axis xyz="0 1 0"/>
    <limit lower="-3.14" upper="3.14" effort="10" velocity="10"/>
  </joint>

  <link name="rf_link_3">
    <visual>
      <origin xyz="0 0 0.02" rpy="0 0 0"/>
      <geometry><cylinder radius="0.008" length="0.04"/></geometry>
      <material name="white">
        <color rgba="1 1 1 1"/>
      </material>
    </visual>
  </link>

  <joint name="th_cmc" type="revolute">
    <parent link="palm"/>
    <child link="th_link_0"/>
    <origin xyz="-0.05 -0.02 0.05" rpy="0 0 0"/>
    <axis xyz="0 1 0"/>
    <limit lower="-3.14" upper="3.14" effort="10" velocity="10"/>
  </joint>

  <link name="th_link_0">
    <visual>
      <origin xyz="0 0 0.02" rpy="0 0 0"/>
      <geometry><cylinder radius="0.008" length="0.04"/></geometry>
      <material name="white">
        <color rgba="1 1 1 1"/>
      </material>
    </visual>
  </link>

  <joint name="th_axl" type="revolute">
    <parent link="th_link_0"/>
    <child link="th_link_1"/>
    <origin xyz="0 0 0.04" rpy="0 0 0"/>
    <axis xyz="0 1 0"/>
    <limit lower="-3.14" upper="3.14" effort="10" velocity="10"/>
  </joint>

  <link name="th_link_1">
    <visual>
      <origin xyz="0 0 0.02" rpy="0 0 0"/>
      <geometry><cylinder radius="0.008" length="0.04"/></geometry>
      <material name="white">
        <color rgba="1 1 1 1"/>
      </material>
    </visual>
  </link>

  <joint name="th_mcp" type="revolute">
    <parent link="th_link_1"/>
    <child link="th_link_2"/>
    <origin xyz="0 0 0.04" rpy="0 0 0"/>
    <axis xyz="0 1 0"/>
    <limit lower="-3.14" upper="3.14" effort="10" velocity="10"/>
  </joint>

  <link name="th_link_2">
    <visual>
      <origin xyz="0 0 0.02" rpy="0 0 0"/>
      <geometry><cylinder radius="0.008" length="0.04"/></geometry>
      <material name="white">
        <color rgba="1 1 1 1"/>
      </material>
    </visual>
  </link>

  <joint name="th_ipl" type="revolute">
    <parent link="th_link_2"/>
    <child link="th_link_3"/>
    <origin xyz="0 0 0.04" rpy="0 0 0"/>
    <axis xyz="0 1 0"/>
    <limit lower="-3.14" upper="3.14" effort="10" velocity="10"/>
  </joint>

  <link name="th_link_3">
    <visual>
      <origin xyz="0 0 0.02" rpy="0 0 0"/>
      <geometry><cylinder radius="0.008" length="0.04"/></geometry>
      <material name="white">
        <color rgba="1 1 1 1"/>
      </material>
    </visual>
  </link>
</robot>
